Workbook

Sheet Hoja1
A1: Codigo | B1: Programa | C1: Campus | D1: Turno | E1: Venta Nueva | F1: Modalidad
A2: 2017479897 | B2: ADMNE | C2: INDEP | D2: A | E2: SI | F2: Presencial
A3: 2017505616 | B3: ADMNI | C3: SURCO | D3: A | E3: SI | F3: Presencial
A4: 2017503757 | B4: GYGEC | C4: VILLA | D4: N | E4: SI | F4: Presencial
A5: 2017505709 | B5: ADMBF | C5: INDEP | D5: N | E5: SI | F5: Presencial
A6: 2017505732 | B6: FISIO | C6: SURCO | D6: C | E6: SI | F6: Presencial
A7: 2017505741 | B7: SWSIS | C7: VILLA | D7: A | E7: SI | F7: Presencial
A8: 2017505760 | B8: SALUD | C8: INDEP | D8: C | E8: SI | F8: Presencial
A9: 2017505803 | B9: DYGMO | C9: STABE | D9: C | E9: SI | F9: Presencial
A10: 2017503832 | B10: DYGMO | C10: ATE | D10: C | E10: SI | F10: Semipresencial
A11: 2017503868 | B11: PA | C11: CANTU | D11: A | E11: SI | F11: Semipresencial
A12: 2017505675 | B12: GYGEC | C12: ATE | D12: A | E12: SI | F12: Semipresencial
A13: 2017505698 | B13: GYGEC | C13: SJL | D13: N | E13: SI | F13: Semipresencial
... A28: 2017418165 | B28: CONTA | C28: VIRTU | D28: M | E28: SI | F28: Virtual

Sheet sheet1
A1: Ciclo | B1: Sección | C1: Nº Clase | D1: Campus | E1: Nombre Curso | F1: Turno | G1: ID Curso | H1: Programa | I1: Venta Nueva | J1: Modalidad | K1: Estado
A2: C1B1 | B2: M0001 | C2: 2026 | D2: STABE | E2: INTRODUCCIÓN A LA MODA | F2: C | G2: 668650 | H2: DYGMO | I2: SI / NO | J2: Presencial | K2: Aperturado
A3: C1B1 | B3: M0001 | C3: 2027 | D3: STABE | E3: DIBUJO TÉCNICO DE LA MODA | F3: C | G3: 668651 | H3: DYGMO | I3: SI / NO | J3: Presencial | K3: Aperturado
A4: C1B1 | B4: M0001 | C4: 1988 | D4: STABE | E4: METOD. PARA UN APREND. EFIC. | F4: C | G4: 668513 | H4: DYGMO | I4: SI / NO | J4: Presencial | K4: Aperturado
A5: C1B1 | B5: M0002 | C5: 1575 | D5: INDEP | E5: INTRODUCCIÓN A LA MODA | F5: C | G5: 668650 | H5: DYGMO | I5: SI / NO | J5: Presencial | K5: Aperturado
A6: C1B1 | B6: M0002 | C6: 1576 | D6: INDEP | E6: DIBUJO TÉCNICO DE LA MODA | F6: C | G6: 668651 | H6: DYGMO | I6: SI / NO | J6: Presencial | K6: Aperturado
A7: C1B1 | B7: M0002 | C7: 1516 | D7: INDEP | E7: METOD. PARA UN APREND. EFIC. | F7: C | G7: 668513 | H7: DYGMO | I7: SI / NO | J7: Presencial | K7: Aperturado
A8: C1B1 | B8: M0004 | C8: 2400 | D8: SURCO | E8: DIBUJO TÉCNICO DE LA MODA | F8: C | G8: 668651 | H8: DYGMO | I8: SI / NO | J8: Presencial | K8: Aperturado
A9: C1B1 | B9: M0004 | C9: 2399 | D9: SURCO | E9: INTRODUCCIÓN A LA MODA | F9: C | G9: 668650 | H9: DYGMO | I9: SI / NO | J9: Presencial | K9: Aperturado
A10: C1B1 | B10: M0004 | C10: 2290 | D10: SURCO | E10: METOD. PARA UN APREND. EFIC. | F10: C | G10: 668513 | H10: DYGMO | I10: SI / NO | J10: Presencial | K10: Aperturado
A11: C1B1 | B11: M0005 | C11: 1759 | D11: SJL | E11: DIBUJO TÉCNICO DE LA MODA | F11: A | G11: 668651 | H11: DYGMO | I11: SI / NO | J11: Presencial | K11: Aperturado
A12: C1B1 | B12: M0005 | C12: 1758 | D12: SJL | E12: INTRODUCCIÓN A LA MODA | F12: A | G12: 668650 | H12: DYGMO | I12: SI / NO | J12: Presencial | K12: Aperturado
A13: C1B1 | B13: M0005 | C13: 1706 | D13: SJL | E13: METOD. PARA UN APREND. EFIC. | F13: A | G13: 668513 | H13: DYGMO | I13: SI / NO | J13: Presencial | K13: Aperturado
... A1059: C1B2 | B1059: I0123 | C1059: 2653 | D1059: VENTN | E1059: T. DE COM. EF. Y RES. DE CONF. | F1059: N | G1059: 668952 | H1059: FISIO | I1059: SI / NO | J1059: Presencial | K1059: Aperturado

Sheet sheet2
A1: Nº Clase | B1: Campus | C1: ID | D1: ID Curso | E1: Nombre Curso | F1: Componente | G1: Sección | H1: Capacidad Inscripción | I1: Tot Inscr | J1: Nombre | K1: Turno Acad | L1: Ciclo | M1: Programas
A2: 2848 | B2: VIRTU | C2: 2017103040 | D2: 668832 | E2: CREATIVIDAD | F2: MIX | G2: 1T6 | H2: 40 | I2: 14 | J2: IPANAQUE PINGO,GISELA ISABEL | K2: N | L2: =VLOOKUP(D2,CONSOLIDADO!$L$1:$AG$893,22,FALSE) -> #N/A | M2: =VLOOKUP(D2,CONSOLIDADO!$L$1:$AI$893,24,FALSE) -> #N/A
A3: 2832 | B3: VIRTU | C3: 2017111229 | D3: 668743 | E3: CREATIVIDAD E INNOVACIÓN | F3: MIX | G3: 2R15 | H3: 40 | I3: 34 | J3: CUYA ESPICHAN,PERCY | K3: N | L3: =VLOOKUP(D3,CONSOLIDADO!$L$1:$AG$893,22,FALSE) -> #N/A | M3: =VLOOKUP(D3,CONSOLIDADO!$L$1:$AI$893,24,FALSE) -> #N/A
A4: 2831 | B4: VIRTU | C4: 2017163027 | D4: 668743 | E4: CREATIVIDAD E INNOVACIÓN | F4: MIX | G4: 2G25 | H4: 40 | I4: 14 | J4: CHIANG DIAZ,CARLOS ALBERTO | K4: M | L4: =VLOOKUP(D4,CONSOLIDADO!$L$1:$AG$893,22,FALSE) -> #N/A | M4: =VLOOKUP(D4,CONSOLIDADO!$L$1:$AI$893,24,FALSE) -> #N/A
A5: 2864 | B5: VIRTU | C5: 2017169984 | D5: 669100 | E5: COMERCIO INTERNACIONAL | F5: MIX | G5: 3S4 | H5: 40 | I5: 28 | J5: SALAZAR MORALES,ANIBAL FRANCISCO | K5: N | L5: =VLOOKUP(D5,CONSOLIDADO!$L$1:$AG$893,22,FALSE) -> #N/A | M5: =VLOOKUP(D5,CONSOLIDADO!$L$1:$AI$893,24,FALSE) -> #N/A
A6: 2806 | B6: VIRTU | C6: 2017185513 | D6: 668528 | E6: T. DE MET. ÁGIL. PARA LA INNO. | F6: MIX | G6: 3W1 | H6: 40 | I6: 27 | J6: Romero Azabache,Miguel Arturo | K6: N | L6: =VLOOKUP(D6,CONSOLIDADO!$L$1:$AG$893,22,FALSE) -> #N/A | M6: =VLOOKUP(D6,CONSOLIDADO!$L$1:$AI$893,24,FALSE) -> #N/A
A7: 2795 | B7: VIRTU | C7: 2017214605 | D7: 668513 | E7: METOD. PARA UN APREND. EFIC. | F7: MIX | G7: 1V9 | H7: 40 | I7: 35 | J7: GONZALEZ ANGELATS,EVA ANA | K7: N | L7: =VLOOKUP(D7,CONSOLIDADO!$L$1:$AG$893,22,FALSE) -> #N/A | M7: =VLOOKUP(D7,CONSOLIDADO!$L$1:$AI$893,24,FALSE) -> #N/A
A8: 2793 | B8: VIRTU | C8: 2017214605 | D8: 668513 | E8: METOD. PARA UN APREND. EFIC. | F8: MIX | G8: 1W1 | H8: 40 | I8: 19 | J8: GONZALEZ ANGELATS,EVA ANA | K8: N | L8: =VLOOKUP(D8,CONSOLIDADO!$L$1:$AG$893,22,FALSE) -> #N/A | M8: =VLOOKUP(D8,CONSOLIDADO!$L$1:$AI$893,24,FALSE) -> #N/A
A9: 2857 | B9: VIRTU | C9: 2017236914 | D9: 668905 | E9: CONTABILIDAD INTERMEDIA | F9: MIX | G9: 3S4 | H9: 40 | I9: 9 | J9: ACUNA APARCANA,ALDO ALI | K9: N | L9: =VLOOKUP(D9,CONSOLIDADO!$L$1:$AG$893,22,FALSE) -> #N/A | M9: =VLOOKUP(D9,CONSOLIDADO!$L$1:$AI$893,24,FALSE) -> #N/A
A10: 2809 | B10: VIRTU | C10: 2017252688 | D10: 668530 | E10: INTRODUCCIÓN DE LAS REDES | F10: MIX | G10: 3V3 | H10: 20 | I10: 12 | J10: ALCANTARA ALVAN,ADRIAN ANGELO | K10: N | L10: =VLOOKUP(D10,CONSOLIDADO!$L$1:$AG$893,22,FALSE) -> #N/A | M10: =VLOOKUP(D10,CONSOLIDADO!$L$1:$AI$893,24,FALSE) -> #N/A
A11: 2830 | B11: VIRTU | C11: 2017266298 | D11: 668742 | E11: CONTABILIDAD I | F11: MIX | G11: 2W1 | H11: 40 | I11: 29 | J11: Lagos Dominguez,Jorge Carlos | K11: N | L11: =VLOOKUP(D11,CONSOLIDADO!$L$1:$AG$893,22,FALSE) -> #N/A | M11: =VLOOKUP(D11,CONSOLIDADO!$L$1:$AI$893,24,FALSE) -> #N/A
A12: 2838 | B12: VIRTU | C12: 2017266298 | D12: 668749 | E12: CONTABILIDAD II | F12: MIX | G12: 3W1 | H12: 40 | I12: 26 | J12: Lagos Dominguez,Jorge Carlos | K12: N | L12: =VLOOKUP(D12,CONSOLIDADO!$L$1:$AG$893,22,FALSE) -> #N/A | M12: =VLOOKUP(D12,CONSOLIDADO!$L$1:$AI$893,24,FALSE) -> #N/A
A13: 2841 | B13: VIRTU | C13: 2017266298 | D13: 668754 | E13: ECONOMÍA PARA LOS NEGOCIOS | F13: MIX | G13: 4W1 | H13: 40 | I13: 14 | J13: Lagos Dominguez,Jorge Carlos | K13: N | L13: =VLOOKUP(D13,CONSOLIDADO!$L$1:$AG$893,22,FALSE) -> #N/A | M13: =VLOOKUP(D13,CONSOLIDADO!$L$1:$AI$893,24,FALSE) -> #N/A
... A36: 2816 | B36: VIRTU | C36: 2017505415 | D36: 668686 | E36: ADMINISTRACIÓN GENERAL | F36: MIX | G36: 1R15 | H36: 40 | I36: 19 | J36: Quiroz Huaman,Sarai Raquel | K36: N | L36: =VLOOKUP(D36,CONSOLIDADO!$L$1:$AG$893,22,FALSE) -> #N/A | M36: =VLOOKUP(D36,CONSOLIDADO!$L$1:$AI$893,24,FALSE) -> #N/A
A37: 2824 | B37: VIRTU | C37: I100000772 | D37: 668741 | E37: ESTADÍS. APLIC. A LOS NEGOCIOS | F37: MIX | G37: 2R15 | H37: 40 | I37: 24 | J37: AGUIRRE QUISPE, YANINA DINA | K37: N | L37: =VLOOKUP(D37,CONSOLIDADO!$L$1:$AG$893,22,FALSE) -> #N/A | M37: =VLOOKUP(D37,CONSOLIDADO!$L$1:$AI$893,24,FALSE) -> #N/A
A38: 2842 | B38: VIRTU | C38: I100000891 | D38: 668755 | E38: ADMINISTRACIÓN DE LA PRODUCCIÓ | F38: MIX | G38: 4R | H38: 40 | I38: 20 | J38: CHUMPITAZ SANCHEZ,VICTOR ANDRES | K38: N | L38: =VLOOKUP(D38,CONSOLIDADO!$L$1:$AG$893,22,FALSE) -> #N/A | M38: =VLOOKUP(D38,CONSOLIDADO!$L$1:$AI$893,24,FALSE) -> #N/A
A39: 2796 | B39: VIRTU | C39: I100000910 | D39: 668514 | E39: REDES DE COMPUTADORAS | F39: MIX | G39: 1V9 | H39: 40 | I39: 15 | J39: CRUZ RAMOS, WALDIR CIRO | K39: N | L39: =VLOOKUP(D39,CONSOLIDADO!$L$1:$AG$893,22,FALSE) -> #N/A | M39: =VLOOKUP(D39,CONSOLIDADO!$L$1:$AI$893,24,FALSE) -> #N/A
A40: 2819 | B40: VIRTU | C40: I100000923 | D40: 668692 | E40: MATEMÁTICA COMERCIAL | F40: MIX | G40: 1G25 | H40: 40 | I40: 18 | J40: DELROSARIO SORIA, PEDRO RICHARD | K40: M | L40: =VLOOKUP(D40,CONSOLIDADO!$L$1:$AG$893,22,FALSE) -> #N/A | M40: =VLOOKUP(D40,CONSOLIDADO!$L$1:$AI$893,24,FALSE) -> #N/A
A41: 2802 | B41: VIRTU | C41: I100000928 | D41: 668516 | E41: T. DE INFORM. PARA LA EMPLEAB. | F41: MIX | G41: 2W1 | H41: 40 | I41: 24 | J41: DELGADO SALAS, EDUARDO MANUEL | K41: N | L41: =VLOOKUP(D41,CONSOLIDADO!$L$1:$AG$893,22,FALSE) -> #N/A | M41: =VLOOKUP(D41,CONSOLIDADO!$L$1:$AI$893,24,FALSE) -> #N/A
A42: 2846 | B42: VIRTU | C42: I100000928 | D42: 668823 | E42: EXCEL AVAN. Y AC. EMPRE. | F42: MIX | G42: 4W1 | H42: 40 | I42: 12 | J42: DELGADO SALAS, EDUARDO MANUEL | K42: N | L42: =VLOOKUP(D42,CONSOLIDADO!$L$1:$AG$893,22,FALSE) -> #N/A | M42: =VLOOKUP(D42,CONSOLIDADO!$L$1:$AI$893,24,FALSE) -> #N/A
A43: 2804 | B43: VIRTU | C43: I100000936 | D43: 668516 | E43: T. DE INFORM. PARA LA EMPLEAB. | F43: MIX | G43: 2V2 | H43: 40 | I43: 17 | J43: DONGO TERNERO,JOSE RICARDO | K43: N | L43: =VLOOKUP(D43,CONSOLIDADO!$L$1:$AG$893,22,FALSE) -> #N/A | M43: =VLOOKUP(D43,CONSOLIDADO!$L$1:$AI$893,24,FALSE) -> #N/A
A44: 2823 | B44: VIRTU | C44: I100000941 | D44: 668705 | E44: FUNDAMENTOS DE MARKETING | F44: MIX | G44: 1W1 | H44: 40 | I44: 19 | J44: ELIAS TEJADA,MARIA YSABEL | K44: N | L44: =VLOOKUP(D44,CONSOLIDADO!$L$1:$AG$893,22,FALSE) -> #N/A | M44: =VLOOKUP(D44,CONSOLIDADO!$L$1:$AI$893,24,FALSE) -> #N/A
A45: 2844 | B45: VIRTU | C45: I100000941 | D45: 668817 | E45: REDACCIÓN COMERCIAL | F45: MIX | G45: 2W1 | H45: 40 | I45: 28 | J45: ELIAS TEJADA,MARIA YSABEL | K45: N | L45: =VLOOKUP(D45,CONSOLIDADO!$L$1:$AG$893,22,FALSE) -> #N/A | M45: =VLOOKUP(D45,CONSOLIDADO!$L$1:$AI$893,24,FALSE) -> #N/A
A46: 2860 | B46: VIRTU | C46: I100000985 | D46: 668952 | E46: T. DE COM. EF. Y RES. DE CONF. | F46: MIX | G46: 1G25 | H46: 40 | I46: 20 | J46: GARRIAZO RAMOS, FLOR DE MARIA | K46: M | L46: =VLOOKUP(D46,CONSOLIDADO!$L$1:$AG$893,22,FALSE) -> #N/A | M46: =VLOOKUP(D46,CONSOLIDADO!$L$1:$AI$893,24,FALSE) -> #N/A
A47: 2790 | B47: VIRTU | C47: I100000996 | D47: 668513 | E47: METOD. PARA UN APREND. EFIC. | F47: MIX | G47: 1R14 | H47: 40 | I47: 38 | J47: GONZALES VALVERDE, LOURDES CECILIA | K47: N | L47: =VLOOKUP(D47,CONSOLIDADO!$L$1:$AG$893,22,FALSE) -> #N/A | M47: =VLOOKUP(D47,CONSOLIDADO!$L$1:$AI$893,24,FALSE) -> #N/A
A48: 2791 | B48: VIRTU | C48: I100000996 | D48: 668513 | E48: METOD. PARA UN APREND. EFIC. | F48: MIX | G48: 1R15 | H48: 40 | I48: 20 | J48: GONZALES VALVERDE, LOURDES CECILIA | K48: N | L48: =VLOOKUP(D48,CONSOLIDADO!$L$1:$AG$893,22,FALSE) -> #N/A | M48: =VLOOKUP(D48,CONSOLIDADO!$L$1:$AI$893,24,FALSE) -> #N/A
... A91: 2866 | B91: VIRTU | C91: I100093338 | D91: 669102 | E91: COMERCIO INTERNACIONAL | F91: MIX | G91: 3W1 | H91: 40 | I91: 28 | J91: CHAVEZ COCA,MONICA | K91: N | L91: =VLOOKUP(D91,CONSOLIDADO!$L$1:$AG$893,22,FALSE) -> #N/A | M91: =VLOOKUP(D91,CONSOLIDADO!$L$1:$AI$893,24,FALSE) -> #N/A
A92: 2684 | B92: VILLA | C92: 100060543 | D92: 668516 | E92: T. DE INFORM. PARA LA EMPLEAB. | F92: MIX | G92: 2X1 | H92: 22 | I92: 18 | J92: DE LA CRUZ RODRIGUEZ,PORFIRIO JIMMY | K92: N | L92: =VLOOKUP(D92,CONSOLIDADO!$L$1:$AG$893,22,FALSE) -> #N/A | M92: =VLOOKUP(D92,CONSOLIDADO!$L$1:$AI$893,24,FALSE) -> #N/A
A93: 2773 | B93: VILLA | C93: 1100001183 | D93: 668952 | E93: T. DE COM. EF. Y RES. DE CONF. | F93: MIX | G93: 1I3 | H93: 35 | I93: 13 | J93: PINGLO VELA,MANUEL | K93: M | L93: =VLOOKUP(D93,CONSOLIDADO!$L$1:$AG$893,22,FALSE) -> #N/A | M93: =VLOOKUP(D93,CONSOLIDADO!$L$1:$AI$893,24,FALSE) -> #N/A
A94: 2892 | B94: VILLA | C94: 1100004606 | D94: 668724 | E94: COCINA LATINOAMERICANA | F94: MIX | G94: 2M11 | H94: 20 | I94: 0 | J94: XXXXXXXX XXXXXXX,XXXXXXXX | K94: T | L94: =VLOOKUP(D94,CONSOLIDADO!$L$1:$AG$893,22,FALSE) -> #N/A | M94: =VLOOKUP(D94,CONSOLIDADO!$L$1:$AI$893,24,FALSE) -> #N/A
A95: 2769 | B95: VILLA | C95: 2017025183 | D95: 668902 | E95: CONTABILIDAD BÁSICA | F95: MIX | G95: 2R | H95: 22 | I95: 1 | J95: Sanchez Roman,Beatriz Alejandra | K95: N | L95: =VLOOKUP(D95,CONSOLIDADO!$L$1:$AG$893,22,FALSE) -> #N/A | M95: =VLOOKUP(D95,CONSOLIDADO!$L$1:$AI$893,24,FALSE) -> #N/A
A96: 2775 | B96: VILLA | C96: 2017095838 | D96: 668952 | E96: T. DE COM. EF. Y RES. DE CONF. | F96: MIX | G96: 1X2 | H96: 34 | I96: 3 | J96: Cerna Pulido,Anthony Toshio Alexander | K96: N | L96: =VLOOKUP(D96,CONSOLIDADO!$L$1:$AG$893,22,FALSE) -> #N/A | M96: =VLOOKUP(D96,CONSOLIDADO!$L$1:$AI$893,24,FALSE) -> #N/A
A97: 2667 | B97: VILLA | C97: 2017104703 | D97: 9044 | E97: AUDITORÍA ADMINISTRATIVA | F97: MIX | G97: 6R | H97: 19 | I97: 10 | J97: Torres Centeno,Fredy Ronald | K97: N | L97: =VLOOKUP(D97,CONSOLIDADO!$L$1:$AG$893,22,FALSE) -> C6B2 | M97: =VLOOKUP(D97,CONSOLIDADO!$L$1:$AI$893,24,FALSE) -> ADMNE
A98: 2779 | B98: VILLA | C98: 2017111229 | D98: 669100 | E98: COMERCIO INTERNACIONAL | F98: MIX | G98: 3R | H98: 40 | I98: 40 | J98: CUYA ESPICHAN,PERCY | K98: N | L98: =VLOOKUP(D98,CONSOLIDADO!$L$1:$AG$893,22,FALSE) -> #N/A | M98: =VLOOKUP(D98,CONSOLIDADO!$L$1:$AI$893,24,FALSE) -> #N/A
A99: 2730 | B99: VILLA | C99: 2017139552 | D99: 668719 | E99: HIGIENE Y SEGURIDAD ALIMENTARI | F99: MIX | G99: 1Z5 | H99: 40 | I99: 19 | J99: VILLANUEVA CARBONERO,JOSE MARTIN RAFAEL | K99: N | L99: =VLOOKUP(D99,CONSOLIDADO!$L$1:$AG$893,22,FALSE) -> #N/A | M99: =VLOOKUP(D99,CONSOLIDADO!$L$1:$AI$893,24,FALSE) -> #N/A
A100: 2704 | B100: VILLA | C100: 2017162082 | D100: 668579 | E100: F. QUÍ. Y BIOQ. EN EL SER HUM. | F100: MIX | G100: 1X2 | H100: 20 | I100: 3 | J100: Vila Sulca,Yusver Isael | K100: N | L100: =VLOOKUP(D100,CONSOLIDADO!$L$1:$AG$893,22,FALSE) -> #N/A | M100: =VLOOKUP(D100,CONSOLIDADO!$L$1:$AI$893,24,FALSE) -> #N/A
A101: 2709 | B101: VILLA | C101: 2017162082 | D101: 668582 | E101: BIOSEGURIDAD | F101: MIX | G101: 2I1 | H101: 40 | I101: 16 | J101: Vila Sulca,Yusver Isael | K101: M | L101: =VLOOKUP(D101,CONSOLIDADO!$L$1:$AG$893,22,FALSE) -> #N/A | M101: =VLOOKUP(D101,CONSOLIDADO!$L$1:$AI$893,24,FALSE) -> #N/A
A102: 2689 | B102: VILLA | C102: 2017163027 | D102: 668528 | E102: T. DE MET. ÁGIL. PARA LA INNO. | F102: MIX | G102: 3G | H102: 40 | I102: 25 | J102: CHIANG DIAZ,CARLOS ALBERTO | K102: M | L102: =VLOOKUP(D102,CONSOLIDADO!$L$1:$AG$893,22,FALSE) -> #N/A | M102: =VLOOKUP(D102,CONSOLIDADO!$L$1:$AI$893,24,FALSE) -> #N/A
A103: 2674 | B103: VILLA | C103: 2017171362 | D103: 668513 | E103: METOD. PARA UN APREND. EFIC. | F103: MIX | G103: 1D | H103: 20 | I103: 16 | J103: Ortega Zorrilla,Ruth Maria | K103: M | L103: =VLOOKUP(D103,CONSOLIDADO!$L$1:$AG$893,22,FALSE) -> #N/A | M103: =VLOOKUP(D103,CONSOLIDADO!$L$1:$AI$893,24,FALSE) -> #N/A
... A166: 2694 | B166: VILLA | C166: 9200910538 | D166: 668535 | E166: T. DE TÉCN. PARA LA ARGUMENT. | F166: MIX | G166: 4I1 | H166: 24 | I166: 17 | J166: MELENDEZ ESPICHAN,JORGE HERNAN | K166: M | L166: =VLOOKUP(D166,CONSOLIDADO!$L$1:$AG$893,22,FALSE) -> #N/A | M166: =VLOOKUP(D166,CONSOLIDADO!$L$1:$AI$893,24,FALSE) -> #N/A
...

Sheet sheet3
A1: Ciclo Lectivo | B1: Institución Académica | C1: Grado Académico | D1: Id_Alumno | E1: Nombre | F1: Programa Académico | G1: Descripción | H1: Plan Académico | I1: C1B1 | J1: C1B2 | K1: C2B1 | L1: C2B2 | M1: C3B1 | N1: C3B2 | O1: C4B1 | P1: C4B2 | Q1: C5B1 | R1: C5B2 | S1: C6B1 | T1: C6B2
A2: 3123 | B2: SISE | C2: PRGS | D2: 100009860 | E2: OSORIO CUYA,JESICA CAROLINA | F2: ADMNE | G2: ADMINISTRACION DE EMPRESAS | H2: ADM2020 | I2: OK | J2: OK | K2: 4 | L2: OK | M2: 4 | N2: 4 | O2: 3 | P2: 4 | Q2: 3 | R2: 4 | S2: 4 | T2: 4
A3: 3123 | B3: SISE | C3: PRGS | D3: 100026056 | E3: CAM SERNA,JHEXAEL YENYHIS | F3: SALUD | G3: ENFERMERIA TECNICA | H3: ENFTEC2020 | I3: OK | J3: OK | K3: OK | L3: 4 | M3: 4 | N3: 5 | O3: 4 | P3: 4 | Q3: 3 | R3: 4 | S3: 4 | T3: 4
A4: 3123 | B4: SISE | C4: PRGS | D4: 100054831 | E4: CARBAJAL ALIPAZAGA,YASUMI ALISON | F4: SALUD | G4: ENFERMERIA TECNICA | H4: ENFTEC2020 | I4: OK | J4: 2 | K4: OK | L4: 4 | M4: 4 | N4: 5 | O4: 4 | P4: 4 | Q4: 3 | R4: 4 | S4: 4 | T4: 4
A5: 3123 | B5: SISE | C5: PRGS | D5: 100072270 | E5: CALLE HUAMAN,CARLOS EDUARDO | F5: SWSIS | G5: DES DE SISTEMAS DE INFORMACION | H5: SOFT2020 | I5: OK | J5: OK | K5: OK | L5: OK | M5: OK | N5: OK | O5: 3 | P5: 4 | Q5: 3 | R5: 4 | S5: 4 | T5: 4
A6: 3123 | B6: SISE | C6: PRGS | D6: 100078635 | E6: CASTRO BRAVO,JEAN PIERRE | F6: ADMLO | G6: GESTIÓN LOGÍSTICA | H6: ADMLO2020 | I6: OK | J6: OK | K6: 4 | L6: 4 | M6: 4 | N6: 4 | O6: 3 | P6: 4 | Q6: 3 | R6: 4 | S6: 4 | T6: 4
A7: 3123 | B7: SISE | C7: PRGS | D7: 100083438 | E7: VILCHEZ TIJERO, PABLO ESTEBAN | F7: SWSIS | G7: DES DE SISTEMAS DE INFORMACION | H7: SOFT2020 | I7: 1 | J7: 1 | K7: 4 | L7: OK | M7: 3 | N7: 4 | O7: 3 | P7: 4 | Q7: 3 | R7: 4 | S7: 4 | T7: 4
A8: 3123 | B8: SISE | C8: PRGS | D8: 2017092999 | E8: CERRON CHAMBERGO,LIZBET KAREN | F8: TECFA | G8: TECNICA EN FARMACIA | H8: TECNFM2020 | I8: OK | J8: 4 | K8: 4 | L8: 4 | M8: 4 | N8: 4 | O8: 4 | P8: 4 | Q8: 4 | R8: 5 | S8: 4 | T8: 5
A9: 3123 | B9: SISE | C9: PRGS | D9: 100086971 | E9: Romo Cotos,Marcos Esteban | F9: ADMBF | G9: ADM. BANCARIA Y FINANCIERA | H9: ABF2020 | I9: OK | J9: OK | K9: 4 | L9: OK | M9: 4 | N9: 4 | O9: 3 | P9: 4 | Q9: 3 | R9: 4 | S9: 4 | T9: 4
A10: 3123 | B10: SISE | C10: PRGS | D10: 100088901 | E10: GARCIA MANCILLA,EVELIN DEYSI | F10: MARKT | G10: MARKETING | H10: MKT2020 | I10: OK | J10: 5 | K10: 4 | L10: 4 | M10: 4 | N10: 4 | O10: 3 | P10: 4 | Q10: 3 | R10: 4 | S10: 4 | T10: 4
A11: 3123 | B11: SISE | C11: PRGS | D11: 1100046612 | E11: GARCIA LUNA, JOSE SANTIAGO CRISTOPHER | F11: SALUD | G11: ENFERMERIA TECNICA | H11: ENFTEC2020 | I11: OK | J11: 6 | K11: 5 | L11: 4 | M11: 4 | N11: 5 | O11: 4 | P11: 4 | Q11: 3 | R11: 4 | S11: 4 | T11: 4
A12: 3123 | B12: SISE | C12: PRGS | D12: 1100072372 | E12: BALDERA TITO, ANGEL ROSSEL | F12: COMAU | G12: COMUNICACION AUDIOVISUAL | H12: COAU2020 | I12: 5 | J12: 5 | K12: 5 | L12: 4 | M12: 4 | N12: 4 | O12: 4 | P12: 4 | Q12: 4 | R12: 4 | S12: 5 | T12: 5
A13: 3123 | B13: SISE | C13: PRGS | D13: 1100081332 | E13: TEJADA DIAZ,ANGIE KRISTEL | F13: ADMNE | G13: ADMINISTRACION DE EMPRESAS | H13: ADM2020 | I13: OK | J13: OK | K13: 4 | L13: OK | M13: 4 | N13: 4 | O13: 3 | P13: 4 | Q13: 3 | R13: 4 | S13: 4 | T13: 4
A14: 3123 | B14: SISE | C14: PRGS | D14: 1100087527 | E14: SORIA CALLAÑAUPA, ESTEFANY DIANA | F14: ADMNE | G14: ADMINISTRACION DE EMPRESAS | H14: ADM2020 | I14: OK | J14: OK | K14: OK | L14: OK | M14: 1 | N14: OK | O14: OK | P14: OK | Q14: OK | R14: 4 | S14: 4 | T14: 4
A15: 3123 | B15: SISE | C15: PRGS | D15: 1100088250 | E15: CARPIO DIPAZ,TEOFILA | F15: COMAU | G15: COMUNICACION AUDIOVISUAL | H15: COAU2020 | I15: OK | J15: OK | K15: 5 | L15: 3 | M15: 4 | N15: 4 | O15: 4 | P15: 4 | Q15: 4 | R15: 4 | S15: 5 | T15: 5
A16: 3123 | B16: SISE | C16: PRGS | D16: 1100089894 | E16: CHUCHEN CARDENAS,SEBASTIAN MATHIAS | F16: REDES | G16: ADM DE REDES Y COMUNICACIONES | H16: RED2020 | I16: 6 | J16: 4 | K16: 4 | L16: 4 | M16: 3 | N16: 4 | O16: 3 | P16: 4 | Q16: 3 | R16: 4 | S16: 4 | T16: 4
A17: 3123 | B17: SISE | C17: PRGS | D17: 1201320407 | E17: Hirata Salvador,Ieykof Michel | F17: FISIO | G17: FISIOTERAPIA Y REHABILITACION | H17: FISYRE2020 | I17: OK | J17: 6 | K17: 5 | L17: 4 | M17: 4 | N17: 5 | O17: 4 | P17: 4 | Q17: 4 | R17: 5 | S17: 4 | T17: 4
A18: 3123 | B18: SISE | C18: PRGS | D18: 1201700494 | E18: REGAL SILVA,MARCELO | F18: COMAU | G18: COMUNICACION AUDIOVISUAL | H18: COAU2020 | I18: 4 | J18: 6 | K18: 5 | L18: 4 | M18: 4 | N18: 4 | O18: 4 | P18: 4 | Q18: 4 | R18: 4 | S18: 5 | T18: 5
A19: 3123 | B19: SISE | C19: PRGS | D19: 2017002838 | E19: CARRERA RICRA,DIANA JHANET | F19: SALUD | G19: ENFERMERIA TECNICA | H19: ENFTEC2020 | I19: OK | J19: OK | K19: OK | L19: OK | M19: OK | N19: OK | O19: 4 | P19: OK | Q19: 3 | R19: 4 | S19: 4 | T19: 4
A20: 3123 | B20: SISE | C20: PRGS | D20: 2017002992 | E20: VASQUEZ TORRES,VALERIA ISABEL | F20: ADMNI | G20: ADM DE NEGOCIOS INTERN | H20: NNII2020 | I20: OK | J20: OK | K20: OK | L20: OK | M20: OK | N20: OK | O20: 3 | P20: 4 | Q20: 3 | R20: 4 | S20: 4 | T20: 4
A21: 3123 | B21: SISE | C21: PRGS | D21: 2017003798 | E21: SANCARRANCO BAYONA,JESUS EDUARDO | F21: DG | G21: DISEÑO GRAFICO PROFESIONAL | H21: DISGRA2020 | I21: OK | J21: OK | K21: 5 | L21: 4 | M21: 4 | N21: 4 | O21: 3 | P21: 4 | Q21: 3 | R21: 5 | S21: 4 | T21: 4
A22: 3123 | B22: SISE | C22: PRGS | D22: 2017006426 | E22: AMACHI UCEDO,LINO JULIAN | F22: DG | G22: DISEÑO GRAFICO PROFESIONAL | H22: DISGRA2020 | I22: OK | J22: OK | K22: OK | L22: OK | M22: 4 | N22: 4 | O22: 3 | P22: 4 | Q22: 3 | R22: 5 | S22: 4 | T22: 4
A23: 3123 | B23: SISE | C23: PRGS | D23: 2017009626 | E23: SUÁREZ RIOS,JHONATAN ELVIS | F23: DG | G23: DISEÑO GRAFICO PROFESIONAL | H23: DISGRA2020 | I23: OK | J23: OK | K23: OK | L23: OK | M23: 4 | N23: 3 | O23: 3 | P23: 4 | Q23: 3 | R23: 5 | S23: 4 | T23: 4
A24: 3123 | B24: SISE | C24: PRGS | D24: 2017010003 | E24: AYALA GARATE,CENAYDA | F24: COMAU | G24: COMUNICACION AUDIOVISUAL | H24: COAU2020 | I24: OK | J24: OK | K24: 1 | L24: OK | M24: OK | N24: OK | O24: OK | P24: OK | Q24: 4 | R24: 4 | S24: 5 | T24: 5
A25: 3123 | B25: SISE | C25: PRGS | D25: 2017012022 | E25: HUERTA ROMERO,SONIA | F25: SALUD | G25: ENFERMERIA TECNICA | H25: ENFTEC2020 | I25: OK | J25: OK | K25: OK | L25: 3 | M25: 4 | N25: 5 | O25: 4 | P25: 4 | Q25: 3 | R25: 4 | S25: 4 | T25: 4
A26: 3123 | B26: SISE | C26: PRGS | D26: 2017012368 | E26: ROSALES HIDALGO,ANGELICA ROSSANA | F26: ADMNE | G26: ADMINISTRACION DE EMPRESAS | H26: ADM2020 | I26: OK | J26: OK | K26: OK | L26: OK | M26: OK | N26: OK | O26: OK | P26: 4 | Q26: 3 | R26: 4 | S26: 4 | T26: 4
A27: 3123 | B27: SISE | C27: PRGS | D27: 2017015666 | E27: HUAMANI VARGAS,MARCO ANDRE | F27: COMAU | G27: COMUNICACION AUDIOVISUAL | H27: COAU2020 | I27: 1 | J27: OK | K27: 5 | L27: 4 | M27: 4 | N27: 4 | O27: 4 | P27: 4 | Q27: 4 | R27: 4 | S27: 5 | T27: 5
A28: 3123 | B28: SISE | C28: PRGS | D28: 2017016000 | E28: MICHUE CHECA,FABRIZIO MICHEL | F28: ADMBF | G28: ADM. BANCARIA Y FINANCIERA | H28: ABF2020 | I28: OK | J28: OK | K28: 4 | L28: 4 | M28: 4 | N28: 4 | O28: 3 | P28: 4 | Q28: 3 | R28: 4 | S28: 4 | T28: 4
A29: 3123 | B29: SISE | C29: PRGS | D29: 2017016618 | E29: ANTEZANA FRAGIDEZ,ELIDIA | F29: SALUD | G29: ENFERMERIA TECNICA | H29: ENFERTECN | I29: OK | J29: 4 | K29: 4 | L29: 5 | M29: 4 | N29: 5 | O29: 4 | P29: 5 | Q29: 3 | R29: 4 | S29: 4 | T29: 4
A30: 3123 | B30: SISE | C30: PRGS | D30: 2017016813 | E30: CORDOVA PIZARRO,AMINADAB | F30: CONTA | G30: CONTABILIDAD | H30: COFI2020 | I30: 4 | J30: 5 | K30: 4 | L30: 4 | M30: 4 | N30: 4 | O30: 3 | P30: 4 | Q30: 3 | R30: 4 | S30: 4 | T30: 4
A31: 3123 | B31: SISE | C31: PRGS | D31: 2017018084 | E31: MELGAREJO RODRIGUEZ,JAIR RODRIGO | F31: DG | G31: DISEÑO GRAFICO PROFESIONAL | H31: DISGRA2020 | I31: 5 | J31: 5 | K31: 5 | L31: 4 | M31: 4 | N31: 4 | O31: 3 | P31: 4 | Q31: 3 | R31: 5 | S31: 4 | T31: 4
A32: 3123 | B32: SISE | C32: PRGS | D32: 2017019575 | E32: VELAZQUEZ DIAZ,GRISEL MEISY | F32: CONTA | G32: CONTABILIDAD | H32: COFI2020 | I32: 2 | J32: 5 | K32: 4 | L32: 4 | M32: 4 | N32: 4 | O32: 3 | P32: 4 | Q32: 3 | R32: 4 | S32: 4 | T32: 4
A33: 3123 | B33: SISE | C33: PRGS | D33: 2017019985 | E33: CARLOS PRIETO,ANGEL GABRIEL | F33: COMAU | G33: COMUNICACION AUDIOVISUAL | H33: COAU2020 | I33: OK | J33: OK | K33: 5 | L33: 4 | M33: 4 | N33: 4 | O33: 4 | P33: 4 | Q33: 4 | R33: 4 | S33: 5 | T33: 5
A34: 3123 | B34: SISE | C34: PRGS | D34: 2017020972 | E34: NINALAYA RODRIGUEZ,YAJAIRA | F34: ADMNE | G34: ADMINISTRACION DE EMPRESAS | H34: ADM2020 | I34: OK | J34: OK | K34: 3 | L34: OK | M34: 4 | N34: 4 | O34: 3 | P34: 4 | Q34: 3 | R34: 4 | S34: 4 | T34: 4
A35: 3123 | B35: SISE | C35: PRGS | D35: 2017021935 | E35: QUITO POLO,DIEGO ADOLFO | F35: ADMNE | G35: ADMINISTRACION DE EMPRESAS | H35: ADM2020 | I35: OK | J35: OK | K35: 4 | L35: OK | M35: 4 | N35: 4 | O35: 3 | P35: 4 | Q35: 3 | R35: 4 | S35: 4 | T35: 4
A36: 3123 | B36: SISE | C36: PRGS | D36: 2017023107 | E36: HERRERA QUINTO,OMAR ALEXIS | F36: GASTR | G36: GASTRONOMIA | H36: GAST2022 | I36: OK | J36: OK | K36: OK | L36: OK | M36: 4 | N36: 4 | O36: 6 | P36: 4
A37: 3123 | B37: SISE | C37: PRGS | D37: 2017023539 | E37: NOLASCO LUME,ROXANA | F37: TECFA | G37: TECNICA EN FARMACIA | H37: TECNFM2020 | I37: 5 | J37: 6 | K37: 5 | L37: 4 | M37: 4 | N37: 4 | O37: 4 | P37: 4 | Q37: 4 | R37: 5 | S37: 4 | T37: 5
A38: 3123 | B38: SISE | C38: PRGS | D38: 2017025086 | E38: CALDERON CANTO,EDGAR | F38: ADMNE | G38: ADMINISTRACION DE EMPRESAS | H38: ADM2020 | I38: OK | J38: 2 | K38: 4 | L38: 1 | M38: 4 | N38: 4 | O38: 3 | P38: 4 | Q38: 3 | R38: 4 | S38: 4 | T38: 4
A39: 3123 | B39: SISE | C39: PRGS | D39: 2017025853 | E39: VENTURO LEON,NINCOL KACELY | F39: COMAU | G39: COMUNICACION AUDIOVISUAL | H39: COAU2020 | I39: 5 | J39: 1 | K39: 5 | L39: 4 | M39: 4 | N39: 4 | O39: 4 | P39: 4 | Q39: 4 | R39: 4 | S39: 5 | T39: 5
A40: 3123 | B40: SISE | C40: PRGS | D40: 2017026543 | E40: AVILA SANCHEZ,ALDHAIR IVAN | F40: DG | G40: DISEÑO GRAFICO PROFESIONAL | H40: DISGRA2020 | I40: OK | J40: 1 | K40: 1 | L40: 1 | M40: 4 | N40: 4 | O40: 3 | P40: 4 | Q40: 3 | R40: 5 | S40: 4 | T40: 4
...

Sheet Hoja3
A1: Sección | B1: Nº Clase | C1: Campus | D1: Nombre Curso | E1: Turno | F1: ID Curso
A2: 1C | B2: 2196 | C2: =VLOOKUP(B2,sheet2!$A$1:$K$1775,2,FALSE) -> #N/A | D2: =VLOOKUP(B2,sheet2!$A$1:$K$1775,5,FALSE) -> #N/A | E2: =VLOOKUP(B2,sheet2!$A$1:$K$1775,11,FALSE) -> #N/A | F2: =VLOOKUP(B2,sheet2!$A$1:$K$1775,4,FALSE) -> #N/A
A3: 1C | B3: 2519 | C3: =VLOOKUP(B3,sheet2!$A$1:$K$1775,2,FALSE) -> SURCO | D3: =VLOOKUP(B3,sheet2!$A$1:$K$1775,5,FALSE) -> CONTABILIDAD BÁSICA | E3: =VLOOKUP(B3,sheet2!$A$1:$K$1775,11,FALSE) -> N | F3: =VLOOKUP(B3,sheet2!$A$1:$K$1775,4,FALSE) -> 668902
A4: 1C | B4: 2503 | C4: =VLOOKUP(B4,sheet2!$A$1:$K$1775,2,FALSE) -> SURCO | D4: =VLOOKUP(B4,sheet2!$A$1:$K$1775,5,FALSE) -> INFOGRAFÍA | E4: =VLOOKUP(B4,sheet2!$A$1:$K$1775,11,FALSE) -> N | F4: =VLOOKUP(B4,sheet2!$A$1:$K$1775,4,FALSE) -> 668848
A5: 1C | B5: 2487 | C5: =VLOOKUP(B5,sheet2!$A$1:$K$1775,2,FALSE) -> SURCO | D5: =VLOOKUP(B5,sheet2!$A$1:$K$1775,5,FALSE) -> EDIC. DIGI.(PREMIERE/AUDITION) | E5: =VLOOKUP(B5,sheet2!$A$1:$K$1775,11,FALSE) -> M | F5: =VLOOKUP(B5,sheet2!$A$1:$K$1775,4,FALSE) -> 668837
A6: 1C1 | B6: 2197 | C6: =VLOOKUP(B6,sheet2!$A$1:$K$1775,2,FALSE) -> #N/A | D6: =VLOOKUP(B6,sheet2!$A$1:$K$1775,5,FALSE) -> #N/A | E6: =VLOOKUP(B6,sheet2!$A$1:$K$1775,11,FALSE) -> #N/A | F6: =VLOOKUP(B6,sheet2!$A$1:$K$1775,4,FALSE) -> #N/A
A7: 1C1 | B7: 2520 | C7: =VLOOKUP(B7,sheet2!$A$1:$K$1775,2,FALSE) -> SURCO | D7: =VLOOKUP(B7,sheet2!$A$1:$K$1775,5,FALSE) -> CONTABILIDAD INTERMEDIA | E7: =VLOOKUP(B7,sheet2!$A$1:$K$1775,11,FALSE) -> M | F7: =VLOOKUP(B7,sheet2!$A$1:$K$1775,4,FALSE) -> 668905
A8: 1C1 | B8: 2504 | C8: =VLOOKUP(B8,sheet2!$A$1:$K$1775,2,FALSE) -> SURCO | D8: =VLOOKUP(B8,sheet2!$A$1:$K$1775,5,FALSE) -> REDACCIÓN DE GUION | E8: =VLOOKUP(B8,sheet2!$A$1:$K$1775,11,FALSE) -> M | F8: =VLOOKUP(B8,sheet2!$A$1:$K$1775,4,FALSE) -> 668864
A9: 1C1 | B9: 2488 | C9: =VLOOKUP(B9,sheet2!$A$1:$K$1775,2,FALSE) -> SURCO | D9: =VLOOKUP(B9,sheet2!$A$1:$K$1775,5,FALSE) -> EDIC. DIGI.(PREMIERE/AUDITION) | E9: =VLOOKUP(B9,sheet2!$A$1:$K$1775,11,FALSE) -> N | F9: =VLOOKUP(B9,sheet2!$A$1:$K$1775,4,FALSE) -> 668837
A10: 1C2 | B10: 2521 | C10: =VLOOKUP(B10,sheet2!$A$1:$K$1775,2,FALSE) -> SURCO | D10: =VLOOKUP(B10,sheet2!$A$1:$K$1775,5,FALSE) -> CONTABILIDAD INTERMEDIA | E10: =VLOOKUP(B10,sheet2!$A$1:$K$1775,11,FALSE) -> N | F10: =VLOOKUP(B10,sheet2!$A$1:$K$1775,4,FALSE) -> 668905
A11: 1C2 | B11: 2489 | C11: =VLOOKUP(B11,sheet2!$A$1:$K$1775,2,FALSE) -> #N/A | D11: =VLOOKUP(B11,sheet2!$A$1:$K$1775,5,FALSE) -> #N/A | E11: =VLOOKUP(B11,sheet2!$A$1:$K$1775,11,FALSE) -> #N/A | F11: =VLOOKUP(B11,sheet2!$A$1:$K$1775,4,FALSE) -> #N/A
A12: 1C2 | B12: 2198 | C12: =VLOOKUP(B12,sheet2!$A$1:$K$1775,2,FALSE) -> #N/A | D12: =VLOOKUP(B12,sheet2!$A$1:$K$1775,5,FALSE) -> #N/A | E12: =VLOOKUP(B12,sheet2!$A$1:$K$1775,11,FALSE) -> #N/A | F12: =VLOOKUP(B12,sheet2!$A$1:$K$1775,4,FALSE) -> #N/A
A13: 1C2 | B13: 2505 | C13: =VLOOKUP(B13,sheet2!$A$1:$K$1775,2,FALSE) -> SURCO | D13: =VLOOKUP(B13,sheet2!$A$1:$K$1775,5,FALSE) -> REDACCIÓN DE GUION | E13: =VLOOKUP(B13,sheet2!$A$1:$K$1775,11,FALSE) -> M | F13: =VLOOKUP(B13,sheet2!$A$1:$K$1775,4,FALSE) -> 668864
... A65: 1C9 | B65: 2534 | C65: =VLOOKUP(B65,sheet2!$A$1:$K$1775,2,FALSE) -> SURCO | D65: =VLOOKUP(B65,sheet2!$A$1:$K$1775,5,FALSE) -> T. DE COM. EF. Y RES. DE CONF. | E65: =VLOOKUP(B65,sheet2!$A$1:$K$1775,11,FALSE) -> M | F65: =VLOOKUP(B65,sheet2!$A$1:$K$1775,4,FALSE) -> 668952
C66: =VLOOKUP(B66,sheet2!$A$1:$K$1775,2,FALSE) -> #N/A | D66: =VLOOKUP(B66,sheet2!$A$1:$K$1775,5,FALSE) -> #N/A | E66: =VLOOKUP(B66,sheet2!$A$1:$K$1775,11,FALSE) -> #N/A | F66: =VLOOKUP(B66,sheet2!$A$1:$K$1775,4,FALSE) -> #N/A
A67: 1D | B67: 2580 | C67: =VLOOKUP(B67,sheet2!$A$1:$K$1775,2,FALSE) -> #N/A | D67: =VLOOKUP(B67,sheet2!$A$1:$K$1775,5,FALSE) -> #N/A | E67: =VLOOKUP(B67,sheet2!$A$1:$K$1775,11,FALSE) -> #N/A | F67: =VLOOKUP(B67,sheet2!$A$1:$K$1775,4,FALSE) -> #N/A
A68: 1D | B68: 2275 | C68: =VLOOKUP(B68,sheet2!$A$1:$K$1775,2,FALSE) -> SURCO | D68: =VLOOKUP(B68,sheet2!$A$1:$K$1775,5,FALSE) -> TRATADOS DE COME INTERNACIONAL | E68: =VLOOKUP(B68,sheet2!$A$1:$K$1775,11,FALSE) -> N | F68: =VLOOKUP(B68,sheet2!$A$1:$K$1775,4,FALSE) -> 9083
A69: 1D | B69: 2256 | C69: =VLOOKUP(B69,sheet2!$A$1:$K$1775,2,FALSE) -> SURCO | D69: =VLOOKUP(B69,sheet2!$A$1:$K$1775,5,FALSE) -> EXPE FORMATIVAS ESPECIALIZADAS | E69: =VLOOKUP(B69,sheet2!$A$1:$K$1775,11,FALSE) -> N | F69: =VLOOKUP(B69,sheet2!$A$1:$K$1775,4,FALSE) -> 9047
A70: 1D1 | B70: 2276 | C70: =VLOOKUP(B70,sheet2!$A$1:$K$1775,2,FALSE) -> SURCO | D70: =VLOOKUP(B70,sheet2!$A$1:$K$1775,5,FALSE) -> PRECI Y COTIZA INTERNACIONALES | E70: =VLOOKUP(B70,sheet2!$A$1:$K$1775,11,FALSE) -> N | F70: =VLOOKUP(B70,sheet2!$A$1:$K$1775,4,FALSE) -> 9100
A71: 1D1 | B71: 2581 | C71: =VLOOKUP(B71,sheet2!$A$1:$K$1775,2,FALSE) -> VENTN | D71: =VLOOKUP(B71,sheet2!$A$1:$K$1775,5,FALSE) -> T. DE INFORM. PARA LA EMPLEAB. | E71: =VLOOKUP(B71,sheet2!$A$1:$K$1775,11,FALSE) -> M | F71: =VLOOKUP(B71,sheet2!$A$1:$K$1775,4,FALSE) -> 668516
A72: 1D1 | B72: 2257 | C72: =VLOOKUP(B72,sheet2!$A$1:$K$1775,2,FALSE) -> SURCO | D72: =VLOOKUP(B72,sheet2!$A$1:$K$1775,5,FALSE) -> GESTIÓN DE CADE DE SUMINISTROS | E72: =VLOOKUP(B72,sheet2!$A$1:$K$1775,11,FALSE) -> N | F72: =VLOOKUP(B72,sheet2!$A$1:$K$1775,4,FALSE) -> 9059
A73: 1D11 | B73: 2277 | C73: =VLOOKUP(B73,sheet2!$A$1:$K$1775,2,FALSE) -> SURCO | D73: =VLOOKUP(B73,sheet2!$A$1:$K$1775,5,FALSE) -> INGLÉS PARA LOS NEGOCIOS III | E73: =VLOOKUP(B73,sheet2!$A$1:$K$1775,11,FALSE) -> N | F73: =VLOOKUP(B73,sheet2!$A$1:$K$1775,4,FALSE) -> 9101
A74: 1D11 | B74: 2582 | C74: =VLOOKUP(B74,sheet2!$A$1:$K$1775,2,FALSE) -> VENTN | D74: =VLOOKUP(B74,sheet2!$A$1:$K$1775,5,FALSE) -> T. DE INFORM. PARA LA EMPLEAB. | E74: =VLOOKUP(B74,sheet2!$A$1:$K$1775,11,FALSE) -> N | F74: =VLOOKUP(B74,sheet2!$A$1:$K$1775,4,FALSE) -> 668516
A75: 1D11 | B75: 2258 | C75: =VLOOKUP(B75,sheet2!$A$1:$K$1775,2,FALSE) -> SURCO | D75: =VLOOKUP(B75,sheet2!$A$1:$K$1775,5,FALSE) -> GEST DE COMER INTERNACIONAL | E75: =VLOOKUP(B75,sheet2!$A$1:$K$1775,11,FALSE) -> N | F75: =VLOOKUP(B75,sheet2!$A$1:$K$1775,4,FALSE) -> 9060
A76: 1D6 | B76: 2265 | C76: =VLOOKUP(B76,sheet2!$A$1:$K$1775,2,FALSE) -> SURCO | D76: =VLOOKUP(B76,sheet2!$A$1:$K$1775,5,FALSE) -> ESTRATEGIA DE COMUNICACIÓN | E76: =VLOOKUP(B76,sheet2!$A$1:$K$1775,11,FALSE) -> M | F76: =VLOOKUP(B76,sheet2!$A$1:$K$1775,4,FALSE) -> 9072
A77: 1D6 | B77: 2589 | C77: =VLOOKUP(B77,sheet2!$A$1:$K$1775,2,FALSE) -> VENTN | D77: =VLOOKUP(B77,sheet2!$A$1:$K$1775,5,FALSE) -> T. DE MET. ÁGIL. PARA LA INNO. | E77: =VLOOKUP(B77,sheet2!$A$1:$K$1775,11,FALSE) -> M | F77: =VLOOKUP(B77,sheet2!$A$1:$K$1775,4,FALSE) -> 668528
A78: 1D6 | B78: 2284 | C78: =VLOOKUP(B78,sheet2!$A$1:$K$1775,2,FALSE) -> SURCO | D78: =VLOOKUP(B78,sheet2!$A$1:$K$1775,5,FALSE) -> METOD. PARA UN APREND. EFIC. | E78: =VLOOKUP(B78,sheet2!$A$1:$K$1775,11,FALSE) -> N | F78: =VLOOKUP(B78,sheet2!$A$1:$K$1775,4,FALSE) -> 668513
... A96: 1D5 | B96: 2283 | C96: =VLOOKUP(B96,sheet2!$A$1:$K$1775,2,FALSE) -> SURCO | D96: =VLOOKUP(B96,sheet2!$A$1:$K$1775,5,FALSE) -> METOD. PARA UN APREND. EFIC. | E96: =VLOOKUP(B96,sheet2!$A$1:$K$1775,11,FALSE) -> M | F96: =VLOOKUP(B96,sheet2!$A$1:$K$1775,4,FALSE) -> 668513
C97: =VLOOKUP(B97,sheet2!$A$1:$K$1775,2,FALSE) -> #N/A | D97: =VLOOKUP(B97,sheet2!$A$1:$K$1775,5,FALSE) -> #N/A | E97: =VLOOKUP(B97,sheet2!$A$1:$K$1775,11,FALSE) -> #N/A | F97: =VLOOKUP(B97,sheet2!$A$1:$K$1775,4,FALSE) -> #N/A
A98: 1U1 | B98: 2624 | C98: =VLOOKUP(B98,sheet2!$A$1:$K$1775,2,FALSE) -> VENTN | D98: =VLOOKUP(B98,sheet2!$A$1:$K$1775,5,FALSE) -> MATEMÁTICA APLICADA EN SALUD | E98: =VLOOKUP(B98,sheet2!$A$1:$K$1775,11,FALSE) -> M | F98: =VLOOKUP(B98,sheet2!$A$1:$K$1775,4,FALSE) -> 668588
A99: 1U1 | B99: 2543 | C99: =VLOOKUP(B99,sheet2!$A$1:$K$1775,2,FALSE) -> SURCO | D99: =VLOOKUP(B99,sheet2!$A$1:$K$1775,5,FALSE) -> DESARROLLO DE ENTORNOS WEB | E99: =VLOOKUP(B99,sheet2!$A$1:$K$1775,11,FALSE) -> N | F99: =VLOOKUP(B99,sheet2!$A$1:$K$1775,4,FALSE) -> 668953
A100: 1U1 | B100: 2535 | C100: =VLOOKUP(B100,sheet2!$A$1:$K$1775,2,FALSE) -> SURCO | D100: =VLOOKUP(B100,sheet2!$A$1:$K$1775,5,FALSE) -> T. DE COM. EF. Y RES. DE CONF. | E100: =VLOOKUP(B100,sheet2!$A$1:$K$1775,11,FALSE) -> M | F100: =VLOOKUP(B100,sheet2!$A$1:$K$1775,4,FALSE) -> 668952
A101: 1U2 | B101: 2544 | C101: =VLOOKUP(B101,sheet2!$A$1:$K$1775,2,FALSE) -> SURCO | D101: =VLOOKUP(B101,sheet2!$A$1:$K$1775,5,FALSE) -> SISTEMAS OPERATIVOS ABIERTOS | E101: =VLOOKUP(B101,sheet2!$A$1:$K$1775,11,FALSE) -> M | F101: =VLOOKUP(B101,sheet2!$A$1:$K$1775,4,FALSE) -> 668955
A102: 1U2 | B102: 2625 | C102: =VLOOKUP(B102,sheet2!$A$1:$K$1775,2,FALSE) -> VENTN | D102: =VLOOKUP(B102,sheet2!$A$1:$K$1775,5,FALSE) -> MATEMÁTICA APLICADA EN SALUD | E102: =VLOOKUP(B102,sheet2!$A$1:$K$1775,11,FALSE) -> N | F102: =VLOOKUP(B102,sheet2!$A$1:$K$1775,4,FALSE) -> 668588
A103: 1U2 | B103: 2536 | C103: =VLOOKUP(B103,sheet2!$A$1:$K$1775,2,FALSE) -> SURCO | D103: =VLOOKUP(B103,sheet2!$A$1:$K$1775,5,FALSE) -> T. DE COM. EF. Y RES. DE CONF. | E103: =VLOOKUP(B103,sheet2!$A$1:$K$1775,11,FALSE) -> M | F103: =VLOOKUP(B103,sheet2!$A$1:$K$1775,4,FALSE) -> 668952
A104: 1U3 | B104: 2626 | C104: =VLOOKUP(B104,sheet2!$A$1:$K$1775,2,FALSE) -> VENTN | D104: =VLOOKUP(B104,sheet2!$A$1:$K$1775,5,FALSE) -> CUID. DE SALUD EN PAC. HOSPIT. | E104: =VLOOKUP(B104,sheet2!$A$1:$K$1775,11,FALSE) -> M | F104: =VLOOKUP(B104,sheet2!$A$1:$K$1775,4,FALSE) -> 668593
A105: 1U3 | B105: 2545 | C105: =VLOOKUP(B105,sheet2!$A$1:$K$1775,2,FALSE) -> SURCO | D105: =VLOOKUP(B105,sheet2!$A$1:$K$1775,5,FALSE) -> SISTEMAS OPERATIVOS ABIERTOS | E105: =VLOOKUP(B105,sheet2!$A$1:$K$1775,11,FALSE) -> N | F105: =VLOOKUP(B105,sheet2!$A$1:$K$1775,4,FALSE) -> 668955
A106: 1U3 | B106: 2537 | C106: =VLOOKUP(B106,sheet2!$A$1:$K$1775,2,FALSE) -> SURCO | D106: =VLOOKUP(B106,sheet2!$A$1:$K$1775,5,FALSE) -> T. DE COM. EF. Y RES. DE CONF. | E106: =VLOOKUP(B106,sheet2!$A$1:$K$1775,11,FALSE) -> N | F106: =VLOOKUP(B106,sheet2!$A$1:$K$1775,4,FALSE) -> 668952
A107: 1U4 | B107: 2546 | C107: =VLOOKUP(B107,sheet2!$A$1:$K$1775,2,FALSE) -> SURCO | D107: =VLOOKUP(B107,sheet2!$A$1:$K$1775,5,FALSE) -> TEO. E HIS. DEL ARTE Y EL DIS. | E107: =VLOOKUP(B107,sheet2!$A$1:$K$1775,11,FALSE) -> N | F107: =VLOOKUP(B107,sheet2!$A$1:$K$1775,4,FALSE) -> 668991
A108: 1U4 | B108: 2538 | C108: =VLOOKUP(B108,sheet2!$A$1:$K$1775,2,FALSE) -> SURCO | D108: =VLOOKUP(B108,sheet2!$A$1:$K$1775,5,FALSE) -> T. DE COM. EF. Y RES. DE CONF. | E108: =VLOOKUP(B108,sheet2!$A$1:$K$1775,11,FALSE) -> N | F108: =VLOOKUP(B108,sheet2!$A$1:$K$1775,4,FALSE) -> 668952
...

Sheet CONSOLIDADO
A1: Institución | B1: Grado | C1: Prog Acad | D1: Plan Acad | E1: Ciclo | F1: Bloque | G1: Descr Corta | H1: Descr | I1: Lista Cso | J1: Descr Corta | K1: Sec Curso | L1: ID Curso | M1: Descr2 | N1: Línea | O1: Descr | P1: Tipo Línea | Q1: Descr | R1: Mín Uni | S1: Máx Uni | T1: OPRID | U1: FECHA | V1: HORA | W1: Gp Cond | X1: Línea | Y1: Tp Req | Z1: Conector | AA1: Corchete_Entrada | AB1: ID Curso | AC1: Descr | AD1: Cond | AE1: Descr | AF1: Corchete_Salida | AG1: Ciclo2 | AH1: Requisito | AI1: Programas
A2: SISE | B2: PRGS | C2: ADMNE | D2: ADM2020 | E2: 0001 | F2: 0001 | G2: AEMC1B1 20 | H2: ADM DE EMPRESAS DCB 2020 | I2: 000000845 | J2: AEMC1B1 20 | K2: 1 | L2: 667275 | M2: ADMINISTRACIÓN GENERAL | N2: 0010 | O2: ADM EMPRESAS DCB 2020 C1B1 | P2: MT | Q2: ADMINISTRACIÓN DE EMPRESAS DCB 2020 C1B1 | R2: 3 | S2: 3 | U2: 26/09/2023 | V2: 01:18:08 p.m. | W2: 001637 | X2: 0010 | Y2: Req Adic | AD2: 000000785 | AE2: ADM BANC DCB 2020 C1B1 | AG2: C1B1 | AH2: NINGUNO | AI2: ADMBF / ADMLO / ADMNE / ADMNI / CONTA / MARKT
A3: SISE | B3: PRGS | C3: ADMNE | D3: ADM2020 | E3: 0001 | F3: 0001 | G3: AEMC1B1 20 | H3: ADM DE EMPRESAS DCB 2020 | I3: 000000845 | J3: AEMC1B1 20 | K3: 2 | L3: 667276 | M3: FUNDAMENTOS DE MARKETING | N3: 0010 | O3: ADM EMPRESAS DCB 2020 C1B1 | P3: MT | Q3: ADMINISTRACIÓN DE EMPRESAS DCB 2020 C1B1 | R3: 2 | S3: 2 | U3: 26/09/2023 | V3: 01:18:08 p.m. | W3: 001637 | X3: 0010 | Y3: Req Adic | AD3: 000000785 | AE3: ADM BANC DCB 2020 C1B1 | AG3: C1B1 | AH3: NINGUNO | AI3: ADMBF / ADMLO / ADMNE / ADMNI / CONTA / MARKT
A4: SISE | B4: PRGS | C4: ADMNE | D4: ADM2020 | E4: 0001 | F4: 0001 | G4: AEMC1B1 20 | H4: ADM DE EMPRESAS DCB 2020 | I4: 000000845 | J4: AEMC1B1 20 | K4: 3 | L4: 667277 | M4: CONTABILIDAD BÁSICA | N4: 0010 | O4: ADM EMPRESAS DCB 2020 C1B1 | P4: MT | Q4: ADMINISTRACIÓN DE EMPRESAS DCB 2020 C1B1 | R4: 4 | S4: 4 | U4: 26/09/2023 | V4: 01:18:08 p.m. | W4: 001637 | X4: 0010 | Y4: Req Adic | AD4: 000000785 | AE4: ADM BANC DCB 2020 C1B1 | AG4: C1B1 | AH4: NINGUNO | AI4: ADMBF / ADMNE / ADMNI / CONTA / MARKT
A5: SISE | B5: PRGS | C5: ADMNE | D5: ADM2020 | E5: 0001 | F5: 0001 | G5: AEMC1B1 20 | H5: ADM DE EMPRESAS DCB 2020 | I5: 000000845 | J5: AEMC1B1 20 | K5: 4 | L5: 667278 | M5: COMUNICACIÓN EFECTIVA | N5: 0010 | O5: ADM EMPRESAS DCB 2020 C1B1 | P5: MT | Q5: ADMINISTRACIÓN DE EMPRESAS DCB 2020 C1B1 | R5: 2 | S5: 2 | U5: 26/09/2023 | V5: 01:18:08 p.m. | W5: 001635 | X5: 0010 | Y5: Req Adic | AD5: 000000773 | AE5: DIS GRAFICO DCB 2020 C1B1 | AG5: C1B1 | AH5: NINGUNO | AI5: ADHYR / ADMBF / ADMLO / ADMNE / ADMNI / COMAU / CONTA / DG / DYGMO / FISIO / GASTR / MARKT / PA / REDES / SALUD / SECRE / SWSIS / TECFA
A6: SISE | B6: PRGS | C6: ADMNE | D6: ADM2020 | E6: 0002 | F6: 0001 | G6: AEMC1B2 20 | H6: ADM DE EMPRESAS DCB 2020 | I6: 000000846 | J6: AEMC1B2 20 | K6: 1 | L6: 667281 | M6: INTRODUCCIÓN AL SISTEMA FINANC | N6: 0020 | O6: ADM EMPRESAS DCB 2020 C1B2 | P6: MT | Q6: ADMINISTRACIÓN DE EMPRESAS DCB 2020 C1B2 | R6: 2 | S6: 2 | U6: 26/09/2023 | V6: 01:18:08 p.m. | W6: 001622 | X6: 0010 | Y6: Req Adic | AD6: 000000822 | AE6: ADM EMPRESAS DCB 2020 C1B2 | AG6: C1B2 | AH6: NINGUNO | AI6: ADMBF / ADMNE / ADMNI / CONTA / MARKT
A7: SISE | B7: PRGS | C7: ADMNE | D7: ADM2020 | E7: 0002 | F7: 0001 | G7: AEMC1B2 20 | H7: ADM DE EMPRESAS DCB 2020 | I7: 000000846 | J7: AEMC1B2 20 | K7: 2 | L7: 667279 | M7: EXCEL PARA LOS NEGOCIOS | N7: 0020 | O7: ADM EMPRESAS DCB 2020 C1B2 | P7: MT | Q7: ADMINISTRACIÓN DE EMPRESAS DCB 2020 C1B2 | R7: 2 | S7: 2 | U7: 26/09/2023 | V7: 01:18:08 p.m. | W7: 001622 | X7: 0010 | Y7: Req Adic | AD7: 000000822 | AE7: ADM EMPRESAS DCB 2020 C1B2 | AG7: C1B2 | AH7: NINGUNO | AI7: ADMBF / ADMLO / ADMNE / ADMNI / CONTA / MARKT
A8: SISE | B8: PRGS | C8: ADMNE | D8: ADM2020 | E8: 0002 | F8: 0001 | G8: AEMC1B2 20 | H8: ADM DE EMPRESAS DCB 2020 | I8: 000000846 | J8: AEMC1B2 20 | K8: 3 | L8: 667280 | M8: TÉCNICAS DE VENTAS | N8: 0020 | O8: ADM EMPRESAS DCB 2020 C1B2 | P8: MT | Q8: ADMINISTRACIÓN DE EMPRESAS DCB 2020 C1B2 | R8: 2 | S8: 2 | U8: 26/09/2023 | V8: 01:18:08 p.m. | W8: 001622 | X8: 0010 | Y8: Req Adic | AD8: 000000822 | AE8: ADM EMPRESAS DCB 2020 C1B2 | AG8: C1B2 | AH8: NINGUNO | AI8: ADMBF / ADMLO / ADMNE / ADMNI / CONTA / MARKT
A9: SISE | B9: PRGS | C9: ADMNE | D9: ADM2020 | E9: 0002 | F9: 0001 | G9: AEMC1B2 20 | H9: ADM DE EMPRESAS DCB 2020 | I9: 000000846 | J9: AEMC1B2 20 | K9: 4 | L9: 667353 | M9: LIDERAZGO Y TRABAJO EN EQUIPO | N9: 0020 | O9: ADM EMPRESAS DCB 2020 C1B2 | P9: MT | Q9: ADMINISTRACIÓN DE EMPRESAS DCB 2020 C1B2 | R9: 3 | S9: 3 | U9: 26/09/2023 | V9: 01:18:08 p.m. | W9: 001623 | X9: 0010 | Y9: Req Adic | AD9: 000000786 | AE9: ADM BANC DCB 2020 C1B2 | AG9: C1B2 | AH9: NINGUNO | AI9: ADHYR / ADMBF / ADMLO / ADMNE / ADMNI / COMAU / CONTA / DG / DYGMO / FISIO / GASTR / MARKT / PA / REDES / SALUD / SECRE / SWSIS / TECFA
A10: SISE | B10: PRGS | C10: ADMNE | D10: ADM2020 | E10: 0002 | F10: 0001 | G10: AEMC1B2 20 | H10: ADM DE EMPRESAS DCB 2020 | I10: 000000846 | J10: AEMC1B2 20 | K10: 5 | L10: 667282 | M10: EDUCACIÓN FINANCIERA (V) | N10: 0020 | O10: ADM EMPRESAS DCB 2020 C1B2 | P10: MT | Q10: ADMINISTRACIÓN DE EMPRESAS DCB 2020 C1B2 | R10: 3 | S10: 3 | U10: 26/09/2023 | V10: 01:18:08 p.m. | W10: 001624 | X10: 0010 | Y10: Req Adic | AD10: 000000786 | AE10: ADM BANC DCB 2020 C1B2 | AG10: C1B2 | AH10: NINGUNO | AI10: ADHYR / ADMBF / ADMLO / ADMNE / ADMNI / COMAU / CONTA / DG / DYGMO / GASTR / MARKT / PA / REDES / SECRE / SWSIS
A11: SISE | B11: PRGS | C11: ADMNE | D11: ADM2020 | E11: 0003 | F11: 0001 | G11: AEMC2B1 20 | H11: ADM DE EMPRESAS DCB 2020 | I11: 000000847 | J11: AEMC2B1 20 | K11: 1 | L11: 667283 | M11: COSTOS Y PRESUPUESTOS | N11: 0030 | O11: ADM EMPRESAS DCB 2020 C2B1 | P11: MT | Q11: ADMINISTRACIÓN DE EMPRESAS DCB 2020 C2B1 | R11: 2 | S11: 2 | U11: 26/09/2023 | V11: 01:18:08 p.m. | W11: 000388 | X11: 0010 | Y11: Req Previo | AB11: 667277 | AC11: CONTABILIDAD BÁSICA | AG11: C2B1 | AH11: CONTABILIDAD BÁSICA | AI11: ADMBF / ADMLO / ADMNE / ADMNI / CONTA / MARKT
A12: SISE | B12: PRGS | C12: ADMNE | D12: ADM2020 | E12: 0003 | F12: 0001 | G12: AEMC2B1 20 | H12: ADM DE EMPRESAS DCB 2020 | I12: 000000847 | J12: AEMC2B1 20 | K12: 2 | L12: 667541 | M12: ÉTICA Y CIUDADANÍA | N12: 0030 | O12: ADM EMPRESAS DCB 2020 C2B1 | P12: MT | Q12: ADMINISTRACIÓN DE EMPRESAS DCB 2020 C2B1 | R12: 2 | S12: 2 | U12: 26/09/2023 | V12: 01:18:08 p.m. | W12: 001636 | X12: 0010 | Y12: Req Adic | AD12: 000000775 | AE12: DIS GRAFICO DCB 2020 C2B1 | AG12: C2B1 | AH12: NINGUNO | AI12: ADHYR / ADMBF / ADMLO / ADMNE / ADMNI / COMAU / CONTA / DG / DYGMO / FISIO / MARKT / PA / REDES / SALUD / SECRE / SWSIS / TECFA
A13: SISE | B13: PRGS | C13: ADMNE | D13: ADM2020 | E13: 0003 | F13: 0001 | G13: AEMC2B1 20 | H13: ADM DE EMPRESAS DCB 2020 | I13: 000000847 | J13: AEMC2B1 20 | K13: 3 | L13: 9010 | M13: COMERCIO INTERNACIONAL | N13: 0030 | O13: ADM EMPRESAS DCB 2020 C2B1 | P13: MT | Q13: ADMINISTRACIÓN DE EMPRESAS DCB 2020 C2B1 | R13: 2 | S13: 2 | U13: 26/09/2023 | V13: 01:18:08 p.m. | W13: 001332 | X13: 0010 | Y13: Req Previo | AB13: 667280 | AC13: TÉCNICAS DE VENTAS | AG13: C2B1 | AH13: TÉCNICAS DE VENTAS | AI13: ADMNE / ADMNI / MARKT
A14: SISE | B14: PRGS | C14: ADMNE | D14: ADM2020 | E14: 0003 | F14: 0001 | G14: AEMC2B1 20 | H14: ADM DE EMPRESAS DCB 2020 | I14: 000000847 | J14: AEMC2B1 20 | K14: 4 | L14: 9011 | M14: INNOVACIÓN Y NEGOCIOS | N14: 0030 | O14: ADM EMPRESAS DCB 2020 C2B1 | P14: MT | Q14: ADMINISTRACIÓN DE EMPRESAS DCB 2020 C2B1 | R14: 2 | S14: 2 | U14: 26/09/2023 | V14: 01:18:08 p.m. | W14: 001655 | X14: 0030 | Y14: Req Adic | AD14: 000000811 | AE14: ADM LOGISTICA DCB 2020 C2B1 | AG14: C2B1 | AH14: NINGUNO | AI14: ADMLO / ADMNE / ADMNI / MARKT
A15: SISE | B15: PRGS | C15: ADMNE | D15: ADM2020 | E15: 0004 | F15: 0001 | G15: AEMC2B2 20 | H15: ADM DE EMPRESAS DCB 2020 | I15: 000000848 | J15: AEMC2B2 20 | K15: 1 | L15: 667285 | M15: LEG COMERCIAL Y TRIBUTARIA | N15: 0040 | O15: ADM EMPRESAS DCB 2020 C2B2 | P15: MT | Q15: ADMINISTRACIÓN DE EMPRESAS DCB 2020 C2B2 | R15: 2 | S15: 2 | U15: 26/09/2023 | V15: 01:18:08 p.m. | W15: 001661 | X15: 0030 | Y15: Req Adic | AD15: 000000788 | AE15: ADM BANC DCB 2020 C2B2 | AG15: C2B2 | AH15: NINGUNO | AI15: ADMBF / ADMLO / ADMNE / ADMNI / CONTA / MARKT
A16: SISE | B16: PRGS | C16: ADMNE | D16: ADM2020 | E16: 0004 | F16: 0001 | G16: AEMC2B2 20 | H16: ADM DE EMPRESAS DCB 2020 | I16: 000000848 | J16: AEMC2B2 20 | K16: 2 | L16: 667286 | M16: MATEMÁTICA COMERCIAL | N16: 0040 | O16: ADM EMPRESAS DCB 2020 C2B2 | P16: MT | Q16: ADMINISTRACIÓN DE EMPRESAS DCB 2020 C2B2 | R16: 2 | S16: 2 | U16: 26/09/2023 | V16: 01:18:08 p.m. | W16: 001669 | X16: 0030 | Y16: Req Adic | AD16: 000000812 | AE16: ADM LOGISTICA DCB 2020 C2B2 | AG16: C2B2 | AH16: NINGUNO | AI16: ADMNE / ADMNI / MARKT
A17: SISE | B17: PRGS | C17: ADMNE | D17: ADM2020 | E17: 0004 | F17: 0001 | G17: AEMC2B2 20 | H17: ADM DE EMPRESAS DCB 2020 | I17: 000000848 | J17: AEMC2B2 20 | K17: 3 | L17: 667287 | M17: SOCIAL MEDIA | N17: 0040 | O17: ADM EMPRESAS DCB 2020 C2B2 | P17: MT | Q17: ADMINISTRACIÓN DE EMPRESAS DCB 2020 C2B2 | R17: 2 | S17: 2 | U17: 26/09/2023 | V17: 01:18:08 p.m. | W17: 001663 | X17: 0010 | Y17: Req Previo | AB17: 667276 | AC17: FUNDAMENTOS DE MARKETING | AG17: C2B2 | AH17: FUNDAMENTOS DE MARKETING | AI17: ADMLO / ADMNE / ADMNI / MARKT
A18: SISE | B18: PRGS | C18: ADMNE | D18: ADM2020 | E18: 0004 | F18: 0001 | G18: AEMC2B2 20 | H18: ADM DE EMPRESAS DCB 2020 | I18: 000000848 | J18: AEMC2B2 20 | K18: 4 | L18: 667288 | M18: EXP FORMA BÁSICAS (HERR INFOR) | N18: 0040 | O18: ADM EMPRESAS DCB 2020 C2B2 | P18: MT | Q18: ADMINISTRACIÓN DE EMPRESAS DCB 2020 C2B2 | R18: 4 | S18: 4 | U18: 26/09/2023 | V18: 01:18:08 p.m. | W18: 001661 | X18: 0030 | Y18: Req Adic | AD18: 000000788 | AE18: ADM BANC DCB 2020 C2B2 | AG18: C2B2 | AH18: NINGUNO | AI18: ADMBF / ADMLO / ADMNE / ADMNI / CONTA / MARKT
A19: SISE | B19: PRGS | C19: ADMNE | D19: ADM2020 | E19: 0005 | F19: 0001 | G19: AEMC3B1 20 | H19: ADM DE EMPRESAS DCB 2020 | I19: 000000849 | J19: AEMC3B1 20 | K19: 1 | L19: 667293 | M19: MATEMÁTICA FINANCIERA | N19: 0050 | O19: ADM EMPRESAS DCB 2020 C3B1 | P19: MT | Q19: ADMINISTRACIÓN DE EMPRESAS DCB 2020 C3B1 | R19: 3 | S19: 3 | U19: 26/09/2023 | V19: 01:18:08 p.m. | W19: 001676 | X19: 0010 | Y19: Req Previo | AB19: 667286 | AC19: MATEMÁTICA COMERCIAL | AG19: C3B1 | AH19: MATEMÁTICA COMERCIAL | AI19: ADMBF / ADMNE / ADMNI / CONTA / MARKT
A20: SISE | B20: PRGS | C20: ADMNE | D20: ADM2020 | E20: 0005 | F20: 0001 | G20: AEMC3B1 20 | H20: ADM DE EMPRESAS DCB 2020 | I20: 000000849 | J20: AEMC3B1 20 | K20: 2 | L20: 667294 | M20: ESTADÍSTICA APLICADA A LOS NEG | N20: 0050 | O20: ADM EMPRESAS DCB 2020 C3B1 | P20: MT | Q20: ADMINISTRACIÓN DE EMPRESAS DCB 2020 C3B1 | R20: 3 | S20: 3 | U20: 26/09/2023 | V20: 01:18:08 p.m. | W20: 001678 | X20: 0010 | Y20: Req Previo | AB20: 667279 | AC20: EXCEL PARA LOS NEGOCIOS | AG20: C3B1 | AH20: EXCEL PARA LOS NEGOCIOS | AI20: ADMBF / ADMLO / ADMNE / ADMNI / CONTA / MARKT
A21: SISE | B21: PRGS | C21: ADMNE | D21: ADM2020 | E21: 0005 | F21: 0001 | G21: AEMC3B1 20 | H21: ADM DE EMPRESAS DCB 2020 | I21: 000000849 | J21: AEMC3B1 20 | K21: 3 | L21: 667295 | M21: GESTIÓN DE CLIENTES - CRM | N21: 0050 | O21: ADM EMPRESAS DCB 2020 C3B1 | P21: MT | Q21: ADMINISTRACIÓN DE EMPRESAS DCB 2020 C3B1 | R21: 3 | S21: 3 | U21: 26/09/2023 | V21: 01:18:08 p.m. | W21: 001682 | X21: 0010 | Y21: Req Previo | AB21: 667287 | AC21: SOCIAL MEDIA | AG21: C3B1 | AH21: SOCIAL MEDIA | AI21: ADMBF / ADMLO / ADMNE / ADMNI / CONTA / MARKT
A22: SISE | B22: PRGS | C22: ADMNE | D22: ADM2020 | E22: 0005 | F22: 0001 | G22: AEMC3B1 20 | H22: ADM DE EMPRESAS DCB 2020 | I22: 000000849 | J22: AEMC3B1 20 | K22: 4 | L22: 667296 | M22: AMBIENTE Y DESARROLLO(VIRTUAL) | N22: 0050 | O22: ADM EMPRESAS DCB 2020 C3B1 | P22: MT | Q22: ADMINISTRACIÓN DE EMPRESAS DCB 2020 C3B1 | R22: 3 | S22: 3 | U22: 26/09/2023 | V22: 01:18:08 p.m. | W22: 001693 | X22: 0010 | Y22: Req Adic | AD22: 000000242 | AE22: DISEÑO GRÁFICO 2017 C3 B2 | AG22: C3B1 | AH22: NINGUNO | AI22: ADHYR / ADMBF / ADMLO / ADMNE / ADMNI / COMAU / CONTA / DG / DYGMO / FISIO / GASTR / MARKT / PA / REDES / SALUD / SECRE / SWSIS / TECFA
A23: SISE | B23: PRGS | C23: ADMNE | D23: ADM2020 | E23: 0006 | F23: 0001 | G23: AEMC3B2 20 | H23: ADM DE EMPRESAS DCB 2020 | I23: 000000850 | J23: AEMC3B2 20 | K23: 1 | L23: 667297 | M23: FINANZAS BÁSICAS | N23: 0060 | O23: ADM EMPRESAS DCB 2020 C3B2 | P23: MT | Q23: ADMINISTRACIÓN DE EMPRESAS DCB 2020 C3B2 | R23: 3 | S23: 3 | U23: 26/09/2023 | V23: 01:18:08 p.m. | W23: 001686 | X23: 0010 | Y23: Req Previo | AB23: 667281 | AC23: INTRODUCCIÓN AL SISTEMA FINANC | AG23: C3B2 | AH23: INTRODUCCIÓN AL SISTEMA FINANC | AI23: ADMBF / ADMLO / ADMNE / ADMNI / CONTA / MARKT
A24: SISE | B24: PRGS | C24: ADMNE | D24: ADM2020 | E24: 0006 | F24: 0001 | G24: AEMC3B2 20 | H24: ADM DE EMPRESAS DCB 2020 | I24: 000000850 | J24: AEMC3B2 20 | K24: 2 | L24: 667298 | M24: CONTABILIDAD APLICADA | N24: 0060 | O24: ADM EMPRESAS DCB 2020 C3B2 | P24: MT | Q24: ADMINISTRACIÓN DE EMPRESAS DCB 2020 C3B2 | R24: 3 | S24: 3 | U24: 26/09/2023 | V24: 01:18:08 p.m. | W24: 001687 | X24: 0010 | Y24: Req Previo | AB24: 667283 | AC24: COSTOS Y PRESUPUESTOS | AG24: C3B2 | AH24: COSTOS Y PRESUPUESTOS | AI24: ADMBF / ADMLO / ADMNE / ADMNI / CONTA / MARKT
A25: SISE | B25: PRGS | C25: ADMNE | D25: ADM2020 | E25: 0006 | F25: 0001 | G25: AEMC3B2 20 | H25: ADM DE EMPRESAS DCB 2020 | I25: 000000850 | J25: AEMC3B2 20 | K25: 3 | L25: 667299 | M25: PLAN DE NEGOCIOS | N25: 0060 | O25: ADM EMPRESAS DCB 2020 C3B2 | P25: MT | Q25: ADMINISTRACIÓN DE EMPRESAS DCB 2020 C3B2 | R25: 3 | S25: 3 | U25: 26/09/2023 | V25: 01:18:08 p.m. | W25: 001691 | X25: 0020 | Y25: Req Adic | AD25: 000000583 | AE25: ADM NEG INTER EXPONENCIAL C3B2 | AG25: C3B2 | AH25: INNOVACIÓN Y NEGOCIOS | AI25: ADMBF / ADMLO / ADMNE / ADMNI / CONTA / MARKT
A26: SISE | B26: PRGS | C26: ADMNE | D26: ADM2020 | E26: 0006 | F26: 0001 | G26: AEMC3B2 20 | H26: ADM DE EMPRESAS DCB 2020 | I26: 000000850 | J26: AEMC3B2 20 | K26: 4 | L26: 667300 | M26: EMPREND Y RESPONS SOCIAL | N26: 0060 | O26: ADM EMPRESAS DCB 2020 C3B2 | P26: MT | Q26: ADMINISTRACIÓN DE EMPRESAS DCB 2020 C3B2 | R26: 3 | S26: 3 | U26: 26/09/2023 | V26: 01:18:08 p.m. | W26: 001692 | X26: 0010 | Y26: Req Adic | AD26: 000000583 | AE26: ADM NEG INTER EXPONENCIAL C3B2 | AG26: C3B2 | AH26: NINGUNO | AI26: ADMBF / ADMLO / ADMNE / ADMNI / CONTA / MARKT
A27: SISE | B27: PRGS | C27: ADMNE | D27: ADM2020 | E27: 0007 | F27: 0001 | G27: AEMC4B1 20 | H27: ADM DE EMPRESAS DCB 2020 | I27: 000000851 | J27: AEMC4B1 20 | K27: 1 | L27: 9025 | M27: INVESTIGACIÓN DE MERCADOS | N27: 0070 | O27: ADM EMPRESAS DCB 2020 C4B1 | P27: MT | Q27: ADMINISTRACIÓN DE EMPRESAS DCB 2020 C4B1 | R27: 2 | S27: 2 | U27: 26/09/2023 | V27: 01:18:08 p.m. | W27: 001334 | X27: 0010 | Y27: Req Previo | AB27: 667294 | AC27: ESTADÍSTICA APLICADA A LOS NEG | AG27: C4B1 | AH27: ESTADÍSTICA APLICADA A LOS NEG | AI27: ADMNE / ADMNI / MARKT
A28: SISE | B28: PRGS | C28: ADMNE | D28: ADM2020 | E28: 0007 | F28: 0001 | G28: AEMC4B1 20 | H28: ADM DE EMPRESAS DCB 2020 | I28: 000000851 | J28: AEMC4B1 20 | K28: 2 | L28: 9026 | M28: ECONOMÍA PARA LOS NEGOCIOS | N28: 0070 | O28: ADM EMPRESAS DCB 2020 C4B1 | P28: MT | Q28: ADMINISTRACIÓN DE EMPRESAS DCB 2020 C4B1 | R28: 3 | S28: 3 | U28: 26/09/2023 | V28: 01:18:08 p.m. | W28: 001701 | X28: 0010 | Y28: Req Adic | AD28: 000000584 | AE28: ADM NEG INTER EXPONENCIAL C4B1 | AG28: C4B1 | AH28: NINGUNO | AI28: ADMNE / ADMNI / MARKT
A29: SISE | B29: PRGS | C29: ADMNE | D29: ADM2020 | E29: 0007 | F29: 0001 | G29: AEMC4B1 20 | H29: ADM DE EMPRESAS DCB 2020 | I29: 000000851 | J29: AEMC4B1 20 | K29: 3 | L29: 9027 | M29: CONTABILIDAD DE COSTOS | N29: 0070 | O29: ADM EMPRESAS DCB 2020 C4B1 | P29: MT | Q29: ADMINISTRACIÓN DE EMPRESAS DCB 2020 C4B1 | R29: 2 | S29: 2 | U29: 26/09/2023 | V29: 01:18:08 p.m. | W29: 001701 | X29: 0010 | Y29: Req Adic | AD29: 000000584 | AE29: ADM NEG INTER EXPONENCIAL C4B1 | AG29: C4B1 | AH29: NINGUNO | AI29: ADMNE / ADMNI / MARKT
A30: SISE | B30: PRGS | C30: ADMNE | D30: ADM2020 | E30: 0008 | F30: 0001 | G30: AEMC4B2 20 | H30: ADM DE EMPRESAS DCB 2020 | I30: 000000852 | J30: AEMC4B2 20 | K30: 1 | L30: 9029 | M30: E-COMMERCE | N30: 0080 | O30: ADM EMPRESAS DCB 2020 C4B2 | P30: MT | Q30: ADMINISTRACIÓN DE EMPRESAS DCB 2020 C4B2 | R30: 2 | S30: 2 | U30: 26/09/2023 | V30: 01:18:08 p.m. | W30: 001335 | X30: 0010 | Y30: Req Previo | AB30: 009010 | AC30: COMERCIO INTERNACIONAL | AG30: C4B2 | AH30: COMERCIO INTERNACIONAL | AI30: ADMNE / ADMNI / MARKT
A31: SISE | B31: PRGS | C31: ADMNE | D31: ADM2020 | E31: 0008 | F31: 0001 | G31: AEMC4B2 20 | H31: ADM DE EMPRESAS DCB 2020 | I31: 000000852 | J31: AEMC4B2 20 | K31: 2 | L31: 9030 | M31: MARKETING DIGITAL | N31: 0080 | O31: ADM EMPRESAS DCB 2020 C4B2 | P31: MT | Q31: ADMINISTRACIÓN DE EMPRESAS DCB 2020 C4B2 | R31: 2 | S31: 2 | U31: 26/09/2023 | V31: 01:18:08 p.m. | W31: 001336 | X31: 0010 | Y31: Req Previo | AB31: 667295 | AC31: GESTIÓN DE CLIENTES - CRM | AG31: C4B2 | AH31: GESTIÓN DE CLIENTES - CRM | AI31: ADMNE / ADMNI / MARKT
A32: SISE | B32: PRGS | C32: ADMNE | D32: ADM2020 | E32: 0008 | F32: 0001 | G32: AEMC4B2 20 | H32: ADM DE EMPRESAS DCB 2020 | I32: 000000852 | J32: AEMC4B2 20 | K32: 3 | L32: 9031 | M32: GESTIÓN ESTRATÉGICA | N32: 0080 | O32: ADM EMPRESAS DCB 2020 C4B2 | P32: MT | Q32: ADMINISTRACIÓN DE EMPRESAS DCB 2020 C4B2 | R32: 2 | S32: 2 | U32: 26/09/2023 | V32: 01:18:08 p.m. | W32: 001720 | X32: 0010 | Y32: Req Adic | AD32: 000000585 | AE32: ADM NEG INTER EXPONENCIAL C4B2 | AG32: C4B2 | AH32: NINGUNO | AI32: ADMNE / MARKT
A33: SISE | B33: PRGS | C33: ADMNE | D33: ADM2020 | E33: 0008 | F33: 0001 | G33: AEMC4B2 20 | H33: ADM DE EMPRESAS DCB 2020 | I33: 000000852 | J33: AEMC4B2 20 | K33: 4 | L33: 9032 | M33: EXPE FORMA INTERME (MKT PER) | N33: 0080 | O33: ADM EMPRESAS DCB 2020 C4B2 | P33: MT | Q33: ADMINISTRACIÓN DE EMPRESAS DCB 2020 C4B2 | R33: 4 | S33: 4 | U33: 26/09/2023 | V33: 01:18:08 p.m. | W33: 001193 | X33: 0010 | Y33: Req Previo | AB33: 667288 | AC33: EXP FORMA BÁSICAS (HERR INFOR) | AG33: C4B2 | AH33: EXP FORMA BÁSICAS (HERR INFOR) | AI33: ADMLO / ADMNE / ADMNI / MARKT
A34: SISE | B34: PRGS | C34: ADMNE | D34: ADM2020 | E34: 0009 | F34: 0001 | G34: AEMC5B1 20 | H34: ADM DE EMPRESAS DCB 2020 | I34: 000000853 | J34: AEMC5B1 20 | K34: 1 | L34: 9033 | M34: LEGISLACIÓN LABORAL | N34: 0090 | O34: ADM EMPRESAS DCB 2020 C5B1 | P34: MT | Q34: ADMINISTRACIÓN DE EMPRESAS DCB 2020 C5B1 | R34: 3 | S34: 3 | U34: 26/09/2023 | V34: 01:18:08 p.m. | W34: 001337 | X34: 0010 | Y34: Req Previo | AB34: 667285 | AC34: LEG COMERCIAL Y TRIBUTARIA | AG34: C5B1 | AH34: LEG COMERCIAL Y TRIBUTARIA | AI34: ADMNE
A35: SISE | B35: PRGS | C35: ADMNE | D35: ADM2020 | E35: 0009 | F35: 0001 | G35: AEMC5B1 20 | H35: ADM DE EMPRESAS DCB 2020 | I35: 000000853 | J35: AEMC5B1 20 | K35: 2 | L35: 9034 | M35: GESTIÓN DE PYMES | N35: 0090 | O35: ADM EMPRESAS DCB 2020 C5B1 | P35: MT | Q35: ADMINISTRACIÓN DE EMPRESAS DCB 2020 C5B1 | R35: 3 | S35: 3 | U35: 26/09/2023 | V35: 01:18:08 p.m. | W35: 001736 | X35: 0010 | Y35: Req Adic | AD35: 000000606 | AE35: ADM EMPRESAS EXPONENCIAL C5B1 | AG35: C5B1 | AH35: NINGUNO | AI35: ADMNE
A36: SISE | B36: PRGS | C36: ADMNE | D36: ADM2020 | E36: 0009 | F36: 0001 | G36: AEMC5B1 20 | H36: ADM DE EMPRESAS DCB 2020 | I36: 000000853 | J36: AEMC5B1 20 | K36: 3 | L36: 9035 | M36: GEST LOGIST Y DE OPERACIONES | N36: 0090 | O36: ADM EMPRESAS DCB 2020 C5B1 | P36: MT | Q36: ADMINISTRACIÓN DE EMPRESAS DCB 2020 C5B1 | R36: 3 | S36: 3 | U36: 26/09/2023 | V36: 01:18:08 p.m. | W36: 001736 | X36: 0010 | Y36: Req Adic | AD36: 000000606 | AE36: ADM EMPRESAS EXPONENCIAL C5B1 | AG36: C5B1 | AH36: NINGUNO | AI36: ADMNE
A37: SISE | B37: PRGS | C37: ADMNE | D37: ADM2020 | E37: 0010 | F37: 0001 | G37: AEMC5B2 20 | H37: ADM DE EMPRESAS DCB 2020 | I37: 000000854 | J37: AEMC5B2 20 | K37: 1 | L37: 9036 | M37: GES DE TE Y DEL CAP DE TRABAJO | N37: 0100 | O37: ADM EMPRESAS DCB 2020 C5B2 | P37: MT | Q37: ADMINISTRACIÓN DE EMPRESAS DCB 2020 C5B2 | R37: 2 | S37: 2 | U37: 26/09/2023 | V37: 01:18:08 p.m. | W37: 001338 | X37: 0010 | Y37: Req Previo | AB37: 667297 | AC37: FINANZAS BÁSICAS | AG37: C5B2 | AH37: FINANZAS BÁSICAS | AI37: ADMNE
A38: SISE | B38: PRGS | C38: ADMNE | D38: ADM2020 | E38: 0010 | F38: 0001 | G38: AEMC5B2 20 | H38: ADM DE EMPRESAS DCB 2020 | I38: 000000854 | J38: AEMC5B2 20 | K38: 2 | L38: 9037 | M38: GESTIÓN DEL TALENTO HUMANO | N38: 0100 | O38: ADM EMPRESAS DCB 2020 C5B2 | P38: MT | Q38: ADMINISTRACIÓN DE EMPRESAS DCB 2020 C5B2 | R38: 3 | S38: 3 | U38: 26/09/2023 | V38: 01:18:08 p.m. | W38: 001743 | X38: 0010 | Y38: Req Adic | AD38: 000000607 | AE38: ADM EMPRESAS EXPONENCIAL C5B2 | AG38: C5B2 | AH38: NINGUNO | AI38: ADMNE
A39: SISE | B39: PRGS | C39: ADMNE | D39: ADM2020 | E39: 0010 | F39: 0001 | G39: AEMC5B2 20 | H39: ADM DE EMPRESAS DCB 2020 | I39: 000000854 | J39: AEMC5B2 20 | K39: 3 | L39: 9038 | M39: ADMINISTRACIÓN PÚBLICA | N39: 0100 | O39: ADM EMPRESAS DCB 2020 C5B2 | P39: MT | Q39: ADMINISTRACIÓN DE EMPRESAS DCB 2020 C5B2 | R39: 3 | S39: 3 | U39: 26/09/2023 | V39: 01:18:08 p.m. | W39: 001743 | X39: 0010 | Y39: Req Adic | AD39: 000000607 | AE39: ADM EMPRESAS EXPONENCIAL C5B2 | AG39: C5B2 | AH39: NINGUNO | AI39: ADMNE
A40: SISE | B40: PRGS | C40: ADMNE | D40: ADM2020 | E40: 0010 | F40: 0001 | G40: AEMC5B2 20 | H40: ADM DE EMPRESAS DCB 2020 | I40: 000000854 | J40: AEMC5B2 20 | K40: 4 | L40: 5437 | M40: INNOVACION TECNOLOGIC(VIRTUAL) | N40: 0100 | O40: ADM EMPRESAS DCB 2020 C5B2 | P40: MT | Q40: ADMINISTRACIÓN DE EMPRESAS DCB 2020 C5B2 | R40: 2 | S40: 2 | U40: 26/09/2023 | V40: 01:18:08 p.m. | W40: 001744 | X40: 0010 | Y40: Req Adic | AD40: 000000587 | AE40: ADM NEG INTER EXPONENCIAL C5B2 | AG40: C5B2 | AH40: NINGUNO | AI40: ADMLO / ADMNE / ADMNI / MARKT
...
